{"uuid": "98f042dc-bb56-457b-94e1-7d332da53091", "children": ["0f3c1b0e-0034-4520-acb8-e3dc9b37b0ee"], "befores": [{"name": "login", "status": "broken", "statusDetails": {"message": "requests.exceptions.ProxyError: HTTPSConnectionPool(host='api.wy56.com', port=443): Max retries exceeded with url: /test/wms-api/system/login (Caused by ProxyError('Cannot connect to proxy.', NewConnectionError('<urllib3.connection.HTTPSConnection object at 0x0000000004A8D100>: Failed to establish a new connection: [WinError 10061] 由于目标计算机积极拒绝，无法连接。')))\n", "trace": "  File \"D:\\Python3\\Proj\\venv\\lib\\site-packages\\pluggy\\_callers.py\", line 39, in _multicall\n    res = hook_impl.function(*args)\n  File \"D:\\Python3\\Proj\\venv\\lib\\site-packages\\_pytest\\fixtures.py\", line 1126, in pytest_fixture_setup\n    result = call_fixture_func(fixturefunc, request, kwargs)\n  File \"D:\\Python3\\Proj\\venv\\lib\\site-packages\\_pytest\\fixtures.py\", line 932, in call_fixture_func\n    fixture_result = fixturefunc(**kwargs)\n  File \"D:\\Python3\\Proj\\testcases\\conftest.py\", line 22, in login\n    rep = RequestUtil().send_request(method, baseinfo[\"base\"][\"login_url\"], data, post_type)\n  File \"D:\\Python3\\Proj\\common\\request_util.py\", line 19, in send_request\n    rep = RequestUtil.session.request(method, url=url, data=data, **kwargs,proxies=proxies,verify=False)\n  File \"D:\\Python3\\Proj\\venv\\lib\\site-packages\\requests\\sessions.py\", line 529, in request\n    resp = self.send(prep, **send_kwargs)\n  File \"D:\\Python3\\Proj\\venv\\lib\\site-packages\\requests\\sessions.py\", line 645, in send\n    r = adapter.send(request, **kwargs)\n  File \"D:\\Python3\\Proj\\venv\\lib\\site-packages\\requests\\adapters.py\", line 513, in send\n    raise ProxyError(e, request=request)\n"}, "start": 1647479303948, "stop": 1647479304956}], "start": 1647479303948, "stop": 1647479305111}